2025-01-31 23:08:49,289 ERROR: Exception on /index [GET] [in C:\Users\owner\Documents\Projects\microblog\venv\Lib\site-packages\flask\app.py:875]
Traceback (most recent call last):
  File "C:\Users\owner\Documents\Projects\microblog\venv\Lib\site-packages\flask\app.py", line 1511, in wsgi_app
    response = self.full_dispatch_request()
  File "C:\Users\owner\Documents\Projects\microblog\venv\Lib\site-packages\flask\app.py", line 919, in full_dispatch_request
    rv = self.handle_user_exception(e)
  File "C:\Users\owner\Documents\Projects\microblog\venv\Lib\site-packages\flask\app.py", line 917, in full_dispatch_request
    rv = self.dispatch_request()
  File "C:\Users\owner\Documents\Projects\microblog\venv\Lib\site-packages\flask\app.py", line 902, in dispatch_request
    return self.ensure_sync(self.view_functions[rule.endpoint])(**view_args)  # type: ignore[no-any-return]
           ~~~~~~~~~~~~~~~~~~~~~~~~~~~~~~~~~~~~~~~~~~~~~~~~~~~~^^^^^^^^^^^^^
  File "C:\Users\owner\Documents\Projects\microblog\venv\Lib\site-packages\flask_login\utils.py", line 290, in decorated_view
    return current_app.ensure_sync(func)(*args, **kwargs)
           ~~~~~~~~~~~~~~~~~~~~~~~~~~~~~^^^^^^^^^^^^^^^^^
  File "C:\Users\owner\Documents\Projects\microblog\app\main\routes.py", line 43, in index
    return render_template('index.html', title=_('Home'), form=form, posts=posts.items, next_url=next_url, prev_url=prev_url)
  File "C:\Users\owner\Documents\Projects\microblog\venv\Lib\site-packages\flask\templating.py", line 150, in render_template
    return _render(app, template, context)
  File "C:\Users\owner\Documents\Projects\microblog\venv\Lib\site-packages\flask\templating.py", line 131, in _render
    rv = template.render(context)
  File "C:\Users\owner\Documents\Projects\microblog\venv\Lib\site-packages\jinja2\environment.py", line 1295, in render
    self.environment.handle_exception()
    ~~~~~~~~~~~~~~~~~~~~~~~~~~~~~~~~~^^
  File "C:\Users\owner\Documents\Projects\microblog\venv\Lib\site-packages\jinja2\environment.py", line 942, in handle_exception
    raise rewrite_traceback_stack(source=source)
  File "C:\Users\owner\Documents\Projects\microblog\app\templates\index.html", line 2, in top-level template code
    {% import "bootstrap_wtf.html" as wtf %}
    ^^^^^^^^^^^^^^^^^^^^^^^^^
  File "C:\Users\owner\Documents\Projects\microblog\app\templates\base.html", line 136, in top-level template code
    {% if curren_user.is_authenticated %}
    ^^^^^^^^^^^^^
  File "C:\Users\owner\Documents\Projects\microblog\venv\Lib\site-packages\jinja2\environment.py", line 490, in getattr
    return getattr(obj, attribute)
jinja2.exceptions.UndefinedError: 'curren_user' is undefined
2025-01-31 23:08:52,560 ERROR: Exception on /index [GET] [in C:\Users\owner\Documents\Projects\microblog\venv\Lib\site-packages\flask\app.py:875]
Traceback (most recent call last):
  File "C:\Users\owner\Documents\Projects\microblog\venv\Lib\site-packages\flask\app.py", line 1511, in wsgi_app
    response = self.full_dispatch_request()
  File "C:\Users\owner\Documents\Projects\microblog\venv\Lib\site-packages\flask\app.py", line 919, in full_dispatch_request
    rv = self.handle_user_exception(e)
  File "C:\Users\owner\Documents\Projects\microblog\venv\Lib\site-packages\flask\app.py", line 917, in full_dispatch_request
    rv = self.dispatch_request()
  File "C:\Users\owner\Documents\Projects\microblog\venv\Lib\site-packages\flask\app.py", line 902, in dispatch_request
    return self.ensure_sync(self.view_functions[rule.endpoint])(**view_args)  # type: ignore[no-any-return]
           ~~~~~~~~~~~~~~~~~~~~~~~~~~~~~~~~~~~~~~~~~~~~~~~~~~~~^^^^^^^^^^^^^
  File "C:\Users\owner\Documents\Projects\microblog\venv\Lib\site-packages\flask_login\utils.py", line 290, in decorated_view
    return current_app.ensure_sync(func)(*args, **kwargs)
           ~~~~~~~~~~~~~~~~~~~~~~~~~~~~~^^^^^^^^^^^^^^^^^
  File "C:\Users\owner\Documents\Projects\microblog\app\main\routes.py", line 43, in index
    return render_template('index.html', title=_('Home'), form=form, posts=posts.items, next_url=next_url, prev_url=prev_url)
  File "C:\Users\owner\Documents\Projects\microblog\venv\Lib\site-packages\flask\templating.py", line 150, in render_template
    return _render(app, template, context)
  File "C:\Users\owner\Documents\Projects\microblog\venv\Lib\site-packages\flask\templating.py", line 131, in _render
    rv = template.render(context)
  File "C:\Users\owner\Documents\Projects\microblog\venv\Lib\site-packages\jinja2\environment.py", line 1295, in render
    self.environment.handle_exception()
    ~~~~~~~~~~~~~~~~~~~~~~~~~~~~~~~~~^^
  File "C:\Users\owner\Documents\Projects\microblog\venv\Lib\site-packages\jinja2\environment.py", line 942, in handle_exception
    raise rewrite_traceback_stack(source=source)
  File "C:\Users\owner\Documents\Projects\microblog\app\templates\index.html", line 2, in top-level template code
    {% import "bootstrap_wtf.html" as wtf %}
    ^^^^^^^^^^^^^^^^^^^^^^^^^
  File "C:\Users\owner\Documents\Projects\microblog\app\templates\base.html", line 136, in top-level template code
    {% if curren_user.is_authenticated %}
    ^^^^^^^^^^^^^
  File "C:\Users\owner\Documents\Projects\microblog\venv\Lib\site-packages\jinja2\environment.py", line 490, in getattr
    return getattr(obj, attribute)
jinja2.exceptions.UndefinedError: 'curren_user' is undefined
2025-01-31 23:09:21,070 INFO: Microblog startup [in C:\Users\owner\Documents\Projects\microblog\app\__init__.py:76]
2025-01-31 23:09:29,742 ERROR: Exception on /messages [GET] [in C:\Users\owner\Documents\Projects\microblog\venv\Lib\site-packages\flask\app.py:875]
Traceback (most recent call last):
  File "C:\Users\owner\Documents\Projects\microblog\venv\Lib\site-packages\flask\app.py", line 1511, in wsgi_app
    response = self.full_dispatch_request()
  File "C:\Users\owner\Documents\Projects\microblog\venv\Lib\site-packages\flask\app.py", line 919, in full_dispatch_request
    rv = self.handle_user_exception(e)
  File "C:\Users\owner\Documents\Projects\microblog\venv\Lib\site-packages\flask\app.py", line 917, in full_dispatch_request
    rv = self.dispatch_request()
  File "C:\Users\owner\Documents\Projects\microblog\venv\Lib\site-packages\flask\app.py", line 902, in dispatch_request
    return self.ensure_sync(self.view_functions[rule.endpoint])(**view_args)  # type: ignore[no-any-return]
           ~~~~~~~~~~~~~~~~~~~~~~~~~~~~~~~~~~~~~~~~~~~~~~~~~~~~^^^^^^^^^^^^^
  File "C:\Users\owner\Documents\Projects\microblog\venv\Lib\site-packages\flask_login\utils.py", line 290, in decorated_view
    return current_app.ensure_sync(func)(*args, **kwargs)
           ~~~~~~~~~~~~~~~~~~~~~~~~~~~~~^^^^^^^^^^^^^^^^^
  File "C:\Users\owner\Documents\Projects\microblog\app\main\routes.py", line 163, in messages
    current_user.add_notification('unread_message_count', 0)
    ^^^^^^^^^^^^^^^^^^^^^^^^^^^^^
AttributeError: 'User' object has no attribute 'add_notification'. Did you mean: 'add_notifications'?
2025-01-31 23:11:15,229 INFO: Microblog startup [in C:\Users\owner\Documents\Projects\microblog\app\__init__.py:76]
2025-01-31 23:11:20,332 INFO: Microblog startup [in C:\Users\owner\Documents\Projects\microblog\app\__init__.py:76]
2025-01-31 23:11:24,059 INFO: Microblog startup [in C:\Users\owner\Documents\Projects\microblog\app\__init__.py:76]
2025-02-01 22:24:37,939 INFO: Microblog startup [in C:\Users\owner\Documents\Projects\microblog\app\__init__.py:76]
2025-02-01 22:25:42,814 INFO: Microblog startup [in C:\Users\owner\Documents\Projects\microblog\app\__init__.py:76]
2025-02-01 23:20:58,410 INFO: Microblog startup [in C:\Users\owner\Documents\Projects\microblog\app\__init__.py:79]
2025-02-01 23:21:10,088 INFO: Microblog startup [in C:\Users\owner\Documents\Projects\microblog\app\__init__.py:79]
2025-02-01 23:23:23,622 INFO: Microblog startup [in C:\Users\owner\Documents\Projects\microblog\app\__init__.py:79]
